<?xml version="1.0" ?>
<!-- =================================================================================== -->
<!-- |    This document was autogenerated by xacro from /root/sam_bot_description/install/sam_bot_description/share/sam_bot_description/src/description/sam_bot_description.urdf | -->
<!-- |    EDITING THIS FILE BY HAND IS NOT RECOMMENDED                                 | -->
<!-- =================================================================================== -->
<robot name="robot_trx">
  <!-- inertial parameter macros -->
  <!-- transmission macros -->
  <link name="car_1_base_footprint"/>
  <link name="car_1_base_link">
    <collision>
      <origin rpy="0 0 0" xyz="0 0 0.18"/>
      <geometry>
        <box size="0.65 0.25 0.18"/>
      </geometry>
    </collision>
    <inertial>
      <origin rpy="1.5707963267948966 0 1.5707963267948966" xyz="0 0 0"/>
      <mass value="5"/>
      <inertia ixx="0.1895416666666667" ixy="0.0" ixz="0.0" iyy="0.20208333333333336" iyz="0.0" izz="0.03954166666666667"/>
    </inertial>
    <visual>
      <origin rpy="0 0 0" xyz="0 0 0.18"/>
      <material name="Cyan">
        <color rgba="0 1.0 1.0 1.0"/>
      </material>
      <geometry>
        <box size="0.65 0.25 0.18"/>
      </geometry>
    </visual>
  </link>
  <link name="drivewhl_rl_link">
    <collision>
      <origin rpy="1.5707963267948966 0 0" xyz="0 0 0"/>
      <geometry>
        <cylinder length="0.06" radius="0.12"/>
      </geometry>
    </collision>
    <inertial>
      <origin rpy="1.5707963267948966 0 0" xyz="0 0 0"/>
      <mass value="0.1"/>
      <inertia ixx="0.00038999999999999994" ixy="0" ixz="0" iyy="0.00038999999999999994" iyz="0" izz="0.00072"/>
    </inertial>
    <visual>
      <origin rpy="1.5707963267948966 0 0" xyz="0 0 0"/>
      <geometry>
        <cylinder length="0.06" radius="0.12"/>
      </geometry>
      <material name="Gray">
        <color rgba="0.5 0.5 0.5 1.0"/>
      </material>
    </visual>
  </link>
  <joint name="drivewhl_rl_joint" type="continuous">
    <parent link="base_link"/>
    <child link="drivewhl_rl_link"/>
    <origin rpy="0 0 0" xyz="-0.11 0.355 -0.06"/>
    <axis xyz="0 1 0"/>
  </joint>
  <link name="drivewhl_rr_link">
    <collision>
      <origin rpy="1.5707963267948966 0 0" xyz="0 0 0"/>
      <geometry>
        <cylinder length="0.06" radius="0.12"/>
      </geometry>
    </collision>
    <inertial>
      <origin rpy="1.5707963267948966 0 0" xyz="0 0 0"/>
      <mass value="0.1"/>
      <inertia ixx="0.00038999999999999994" ixy="0" ixz="0" iyy="0.00038999999999999994" iyz="0" izz="0.00072"/>
    </inertial>
    <visual>
      <origin rpy="1.5707963267948966 0 0" xyz="0 0 0"/>
      <geometry>
        <cylinder length="0.06" radius="0.12"/>
      </geometry>
      <material name="Gray">
        <color rgba="0.5 0.5 0.5 1.0"/>
      </material>
    </visual>
  </link>
  <joint name="drivewhl_rr_joint" type="continuous">
    <parent link="base_link"/>
    <child link="drivewhl_rr_link"/>
    <origin rpy="0 0 0" xyz="-0.11 -0.355 -0.06"/>
    <axis xyz="0 1 0"/>
  </joint>
  <link name="drivewhl_fl_link">
    <collision>
      <origin rpy="1.5707963267948966 0 0" xyz="0 0 0"/>
      <geometry>
        <cylinder length="0.06" radius="0.12"/>
      </geometry>
    </collision>
    <inertial>
      <origin rpy="1.5707963267948966 0 0" xyz="0 0 0"/>
      <mass value="0.1"/>
      <inertia ixx="0.00038999999999999994" ixy="0" ixz="0" iyy="0.00038999999999999994" iyz="0" izz="0.00072"/>
    </inertial>
    <visual>
      <origin rpy="1.5707963267948966 0 0" xyz="0 0 0"/>
      <geometry>
        <cylinder length="0.06" radius="0.12"/>
      </geometry>
      <material name="Gray">
        <color rgba="0.5 0.5 0.5 1.0"/>
      </material>
    </visual>
  </link>
  <joint name="drivewhl_fl_joint" type="continuous">
    <parent link="base_link"/>
    <child link="drivewhl_fl_link"/>
    <origin rpy="0 0 0" xyz="0.11 0.355 -0.06"/>
    <axis xyz="0 1 0"/>
  </joint>
  <link name="drivewhl_fr_link">
    <collision>
      <origin rpy="1.5707963267948966 0 0" xyz="0 0 0"/>
      <geometry>
        <cylinder length="0.06" radius="0.12"/>
      </geometry>
    </collision>
    <inertial>
      <origin rpy="1.5707963267948966 0 0" xyz="0 0 0"/>
      <mass value="0.1"/>
      <inertia ixx="0.00038999999999999994" ixy="0" ixz="0" iyy="0.00038999999999999994" iyz="0" izz="0.00072"/>
    </inertial>
    <visual>
      <origin rpy="1.5707963267948966 0 0" xyz="0 0 0"/>
      <geometry>
        <cylinder length="0.06" radius="0.12"/>
      </geometry>
      <material name="Gray">
        <color rgba="0.5 0.5 0.5 1.0"/>
      </material>
    </visual>
  </link>
  <joint name="drivewhl_fr_joint" type="continuous">
    <parent link="base_link"/>
    <child link="drivewhl_fr_link"/>
    <origin rpy="0 0 0" xyz="0.11 -0.355 -0.06"/>
    <axis xyz="0 1 0"/>
  </joint>
  <link name="drivewhl_ml_link">
    <collision>
      <origin rpy="1.5707963267948966 0 0" xyz="0 0 0"/>
      <geometry>
        <cylinder length="0.06" radius="0.12"/>
      </geometry>
    </collision>
    <inertial>
      <origin rpy="1.5707963267948966 0 0" xyz="0 0 0"/>
      <mass value="0.1"/>
      <inertia ixx="0.00038999999999999994" ixy="0" ixz="0" iyy="0.00038999999999999994" iyz="0" izz="0.00072"/>
    </inertial>
    <visual>
      <origin rpy="1.5707963267948966 0 0" xyz="0 0 0"/>
      <geometry>
        <cylinder length="0.06" radius="0.12"/>
      </geometry>
      <material name="Gray">
        <color rgba="0.5 0.5 0.5 1.0"/>
      </material>
    </visual>
  </link>
  <joint name="drivewhl_ml_joint" type="continuous">
    <parent link="base_link"/>
    <child link="drivewhl_ml_link"/>
    <origin rpy="0 0 0" xyz="-0.22 0.355 -0.06"/>
    <axis xyz="0 1 0"/>
  </joint>
  <link name="drivewhl_mr_link">
    <collision>
      <origin rpy="1.5707963267948966 0 0" xyz="0 0 0"/>
      <geometry>
        <cylinder length="0.06" radius="0.12"/>
      </geometry>
    </collision>
    <inertial>
      <origin rpy="1.5707963267948966 0 0" xyz="0 0 0"/>
      <mass value="0.1"/>
      <inertia ixx="0.00038999999999999994" ixy="0" ixz="0" iyy="0.00038999999999999994" iyz="0" izz="0.00072"/>
    </inertial>
    <visual>
      <origin rpy="1.5707963267948966 0 0" xyz="0 0 0"/>
      <geometry>
        <cylinder length="0.06" radius="0.12"/>
      </geometry>
      <material name="Gray">
        <color rgba="0.5 0.5 0.5 1.0"/>
      </material>
    </visual>
  </link>
  <joint name="drivewhl_mr_joint" type="continuous">
    <parent link="base_link"/>
    <child link="drivewhl_mr_link"/>
    <origin rpy="0 0 0" xyz="-0.22 -0.355 -0.06"/>
    <axis xyz="0 1 0"/>
  </joint>
  <transmission name="drivewhl_rl_transmission" type="SimpleTransmission">
    <type>transmission_interface/SimpleTransmission</type>
    <joint name="drivewhl_rl_joint">
      <hardwareInterface>hardware_interface/EffortJointInterface</hardwareInterface>
    </joint>
    <actuator name="drivewhl_rl_motor">
      <hardwareInterface>hardware_interface/EffortJointInterface</hardwareInterface>
      <mechanicalReduction>1</mechanicalReduction>
    </actuator>
  </transmission>
  <transmission name="drivewhl_rr_transmission" type="SimpleTransmission">
    <type>transmission_interface/SimpleTransmission</type>
    <joint name="drivewhl_rr_joint">
      <hardwareInterface>hardware_interface/EffortJointInterface</hardwareInterface>
    </joint>
    <actuator name="drivewhl_rr_motor">
      <hardwareInterface>hardware_interface/EffortJointInterface</hardwareInterface>
      <mechanicalReduction>1</mechanicalReduction>
    </actuator>
  </transmission>
  <transmission name="drivewhl_fl_transmission" type="SimpleTransmission">
    <type>transmission_interface/SimpleTransmission</type>
    <joint name="drivewhl_fl_joint">
      <hardwareInterface>hardware_interface/EffortJointInterface</hardwareInterface>
    </joint>
    <actuator name="drivewhl_fl_motor">
      <hardwareInterface>hardware_interface/EffortJointInterface</hardwareInterface>
      <mechanicalReduction>1</mechanicalReduction>
    </actuator>
  </transmission>
  <transmission name="drivewhl_fr_transmission" type="SimpleTransmission">
    <type>transmission_interface/SimpleTransmission</type>
    <joint name="drivewhl_fr_joint">
      <hardwareInterface>hardware_interface/EffortJointInterface</hardwareInterface>
    </joint>
    <actuator name="drivewhl_fr_motor">
      <hardwareInterface>hardware_interface/EffortJointInterface</hardwareInterface>
      <mechanicalReduction>1</mechanicalReduction>
    </actuator>
  </transmission>
  <transmission name="drivewhl_ml_transmission" type="SimpleTransmission">
    <type>transmission_interface/SimpleTransmission</type>
    <joint name="drivewhl_ml_joint">
      <hardwareInterface>hardware_interface/EffortJointInterface</hardwareInterface>
    </joint>
    <actuator name="drivewhl_ml_motor">
      <hardwareInterface>hardware_interface/EffortJointInterface</hardwareInterface>
      <mechanicalReduction>1</mechanicalReduction>
    </actuator>
  </transmission>
  <transmission name="drivewhl_mr_transmission" type="SimpleTransmission">
    <type>transmission_interface/SimpleTransmission</type>
    <joint name="drivewhl_mr_joint">
      <hardwareInterface>hardware_interface/EffortJointInterface</hardwareInterface>
    </joint>
    <actuator name="drivewhl_mr_motor">
      <hardwareInterface>hardware_interface/EffortJointInterface</hardwareInterface>
      <mechanicalReduction>1</mechanicalReduction>
    </actuator>
  </transmission>
  <!-- Add the left steering hinge with its joints and tranmissions -->
  <link name="car_1_left_steering_hinge">
    <inertial>
      <origin rpy="0 0 0" xyz="0 0 0"/>
      <mass value="0.100"/>
      <inertia ixx="4E-06" ixy="0" ixz="0" iyy="4E-06" iyz="0" izz="4E-06"/>
    </inertial>
  </link>
  <joint name="car_1_left_steering_hinge_joint" type="revolute">
    <origin rpy="0 1.5707963267948966 0" xyz="0.325 0.1 0"/>
    <parent link="car_1_base_link"/>
    <child link="car_1_left_steering_hinge"/>
    <axis xyz="-1 0 0"/>
    <limit effort="10" lower="-0.7853981633974483" upper="0.7853981633974483" velocity="100"/>
  </joint>
  <transmission name="car_1_left_steering_hinge_transmission" type="SimpleTransmission">
    <type>transmission_interface/SimpleTransmission</type>
    <joint name="car_1_left_steering_hinge_joint">
      <hardwareInterface>hardware_interface/EffortJointInterface</hardwareInterface>
    </joint>
    <actuator name="car_1_left_steering_hinge_motor">
      <hardwareInterface>hardware_interface/EffortJointInterface</hardwareInterface>
      <mechanicalReduction>1</mechanicalReduction>
    </actuator>
  </transmission>
  <!-- Add the right steering hinge with its joints and tranmissions -->
  <link name="car_1_right_steering_hinge">
    <inertial>
      <origin rpy="0 0 0" xyz="0 0 0"/>
      <mass value="0.100"/>
      <inertia ixx="4E-06" ixy="0" ixz="0" iyy="4E-06" iyz="0" izz="4E-06"/>
    </inertial>
  </link>
  <joint name="car_1_right_steering_hinge_joint" type="revolute">
    <origin rpy="0 1.5707963267948966 0" xyz="0.325 -0.1 0"/>
    <parent link="car_1_base_link"/>
    <child link="car_1_right_steering_hinge"/>
    <axis xyz="-1 0 0"/>
    <limit effort="10" lower="-0.7853981633974483" upper="0.7853981633974483" velocity="100"/>
  </joint>
  <transmission name="car_1_right_steering_hinge_transmission" type="SimpleTransmission">
    <type>transmission_interface/SimpleTransmission</type>
    <joint name="car_1_right_steering_hinge_joint">
      <hardwareInterface>hardware_interface/EffortJointInterface</hardwareInterface>
    </joint>
    <actuator name="car_1_right_steering_hinge_motor">
      <hardwareInterface>hardware_interface/EffortJointInterface</hardwareInterface>
      <mechanicalReduction>1</mechanicalReduction>
    </actuator>
  </transmission>
</robot>
