<?xml version="1.0" ?>
<robot name="trx6_mobile" xmlns:xacro="http://ros.org/wiki/xacro">
  <!-- pi:= 3.141592654  --> <!-- pi/2 1.5707963267949 -->

  <!-- ****************** ROBOT CONSTANTS *******************************  -->
  <!-- Define the name and color of the car -->
  <xacro:arg name="robot_name" default="trx6_mobile" />
  <xacro:arg name="robot_skin" default="Red" />
 
  <!-- Define the size of the robot's main chassis in meters -->
  <xacro:property name="base_width"  value="0.25"/> <!-- 0.39 -->
  <xacro:property name="base_length" value="0.65"/> <!-- 0.70 -->
  <xacro:property name="base_height" value="0.18"/> <!-- 0.20 -->
	
  <!-- Define the shape of the robot's two back wheels in meters -->
  <xacro:property name="wheel_width"  value="0.06"/>
  <xacro:property name="wheel_radius" value="0.10"/> <!-- 0.14 -->

  <!-- Define the shape of the Velodyne VLP-16 LIDAR in meters -->
  <xacro:property name="lidar_width"  value="0.06"/>
  <xacro:property name="lidar_radius" value="0.10"/>

  <!-- x-axis points forward, y-axis points to left, z-axis points upwards -->
  <!-- Define the gap between the wheel and chassis along y-axis in meters -->
  <xacro:property name="wheel_ygap" value="0.025"/> <!-- 0.035 -->

  <!-- Position the wheels along the z-axis -->
  <xacro:property name="wheel_zoff" value="0.05"/>

  <!-- Position the wheels along the x-axis -->
  <xacro:property name="wheel_xoff" value="0.221"/>

  <!-- Position the caster wheel along the x-axis -->
  <xacro:property name="caster_xoff" value="0.217"/>

  <!-- Define intertial property macros  -->
  <xacro:macro name="box_inertia" params="m w h d">
    <inertial>
      <origin xyz="0 0 0" rpy="${pi/2} 0 ${pi/2}"/>
      <mass value="${m}"/>
      <inertia ixx="${(m/12) * (h*h + d*d)}" ixy="0.0" ixz="0.0" iyy="${(m/12) * (w*w + d*d)}" iyz="0.0" izz="${(m/12) * (w*w + h*h)}"/>
    </inertial>
  </xacro:macro>

  <xacro:macro name="cylinder_inertia" params="m r h">
    <inertial>
      <origin xyz="0 0 0" rpy="${pi/2} 0 0" />
      <mass value="${m}"/>
      <inertia ixx="${(m/12) * (3*r*r + h*h)}" ixy = "0" ixz = "0" iyy="${(m/12) * (3*r*r + h*h)}" iyz = "0" izz="${(m/2) * (r*r)}"/>
    </inertial>
  </xacro:macro>

  <xacro:macro name="sphere_inertia" params="m r">
    <inertial>
      <mass value="${m}"/>
      <inertia ixx="${(2/5) * m * (r*r)}" ixy="0.0" ixz="0.0" iyy="${(2/5) * m * (r*r)}" iyz="0.0" izz="${(2/5) * m * (r*r)}"/>
    </inertial>
  </xacro:macro>

  <!-- steering hinge inertias TODO: "intertias" is not grammatically correct :) -->
  <xacro:macro name="steering_hinge_inertial_params">
    <origin xyz="0 0 0" rpy="0 0 0" />
    <mass value="0.100" />
    <inertia ixx="4E-06" ixy="0" ixz="0" iyy="4E-06"  iyz="0" izz="4E-06" />
  </xacro:macro>

  <!-- transmission macros -->
  <xacro:macro name="wheel_transmission" params="name">
    <transmission name="${name}_transmission" type="SimpleTransmission">
      <type>transmission_interface/SimpleTransmission</type>
      <joint name="${name}_joint">
        <hardwareInterface>hardware_interface/EffortJointInterface</hardwareInterface>
      </joint>
      <actuator name="${name}_motor">
        <hardwareInterface>hardware_interface/EffortJointInterface</hardwareInterface>
        <mechanicalReduction>1</mechanicalReduction>
      </actuator>
    </transmission>
  </xacro:macro>

  <xacro:macro name="steering_hinge_transmission" params="name">
    <transmission name="${name}_transmission" type="SimpleTransmission">
      <type>transmission_interface/SimpleTransmission</type>
      <joint name="${name}_joint">
        <hardwareInterface>hardware_interface/EffortJointInterface</hardwareInterface>
      </joint>
      <actuator name="${name}_motor">
        <hardwareInterface>hardware_interface/EffortJointInterface</hardwareInterface>
        <mechanicalReduction>1</mechanicalReduction>
      </actuator>
    </transmission>
  </xacro:macro>

  <!-- ****************** ROBOT BASE FOOTPRINT ***************************  -->
  <!-- Define the center of the main robot chassis projected on the ground -->	
  <link name="base_footprint"/>

  <!-- The base footprint of the robot is located underneath the chassis -->
  <joint name="base_joint" type="fixed">
    <parent link="base_footprint"/>
    <child link="base_link" />
    <origin xyz="0.0 0.0 ${(wheel_radius+wheel_zoff)}" rpy="0 0 0"/>
  </joint>

  <!-- ********************** ROBOT BASE *********************************  -->
  <link name="base_link">
    <visual>
      <origin xyz="0 0 -0.05" rpy="${pi/2} 0 ${pi}"/>
      <geometry>
        <mesh filename="package://trx6_mobile_robot/meshes/robot_base.stl" />
      </geometry>
      <material name="Red">
        <color rgba="${255/255} ${0/255} ${0/255} 1.0"/>
      </material>
    </visual>

    <collision>
      <geometry>
        <box size="${base_length} ${base_width} ${base_height}"/>
      </geometry>
    </collision>

    <!-- TODO: m is the mass of the car and needed to be filled correctly below -->
    <xacro:box_inertia m="40.0" w="${base_width}" d="${base_length}" h="${base_height}"/>
    
  </link>

  <gazebo reference="base_link">
    <material>Gazebo/Red</material>
  </gazebo>

  <!-- *********************** DRIVE WHEELS ******************************  -->

  <xacro:macro name="wheel" params="prefix x_reflect y_reflect">
    <link name="${prefix}_link">
      <visual>
        <origin xyz="0 0 0" rpy="${pi/2} 0 0"/>
        <geometry>
            <cylinder radius="${wheel_radius}" length="${wheel_width}"/>
        </geometry>
        <material name="White">
          <color rgba="${255/255} ${255/255} ${255/255} 1.0"/>
        </material>
      </visual>
      
      <collision>
        <origin xyz="0 0 0" rpy="${pi/2} 0 0"/>
        <geometry>
          <cylinder radius="${wheel_radius}" length="${wheel_width}"/>
        </geometry>
      </collision>
      
    <!-- TODO: m is the mass of the wheel and needed to be filled correctly below -->
      <xacro:cylinder_inertia m="110.5" r="${wheel_radius}" h="${wheel_width}"/>
      
    </link>

    <!-- Connect the wheels to the base_link at the appropriate location, and 
         define a continuous joint to allow the wheels to freely rotate about
         an axis -->
    <joint name="${prefix}_joint" type="revolute">
      <parent link="base_link"/>
      <child link="${prefix}_link"/>
      <origin xyz="${x_reflect*wheel_xoff} ${y_reflect*(base_width/2+wheel_ygap)} ${-wheel_zoff}" rpy="0 0 0"/>
      <limit upper="${pi}" lower="${-pi}" effort="30" velocity="5.0"/>
      <!--limit upper="3.1415" lower="-3.1415" effort="30" velocity="5.0"/-->
      <axis xyz="0 1 0"/>
    </joint>
  </xacro:macro>

  <!-- Instantiate two wheels using the macro we just made through the 
       xacro:wheel tags. We also define the parameters to have one wheel
       on both sides at the back of our robot (i.e. x_reflect=-1). -->
  <xacro:wheel prefix="drivewhl_rear_l" x_reflect="-1" y_reflect="1" />
  <xacro:wheel prefix="drivewhl_rear_r" x_reflect="-1" y_reflect="-1" />
  <xacro:wheel prefix="drivewhl_mid_l" x_reflect="0" y_reflect="1" />
  <xacro:wheel prefix="drivewhl_mid_r" x_reflect="0" y_reflect="-1" />

  <!-- *********************** STEERING WHEEL ******************************  -->
  <!-- We add a pair of steering wheels. It will be modeled as two cylinder.
       We define the wheel’s geometry, material and the joint to connect it to 
       base_link at the appropriate location. -->
  <xacro:wheel prefix="drivewhl_front_l" x_reflect="+1" y_reflect="1" />
  <xacro:wheel prefix="drivewhl_front_r" x_reflect="+1" y_reflect="-1" />
  
  <!-- Each sensor must be attached to a link.                              --> 
  <!-- *********************** IMU SETUP *********************************  -->
  <joint name="imu_joint" type="fixed">
    <parent link="base_link"/>
    <child link="imu_link"/>
    <origin xyz="-0.10 0 0.05" rpy="0 0 0"/>
  </joint>

  <link name="imu_link"/>

  <!-- *********************** LIDAR SETUP *********************************  -->
  <joint name="lidar_joint" type="fixed">
    <parent link="base_link"/>
    <child link="lidar_link"/>
    <origin xyz="0 0 0.15" rpy="0 0 0"/>
  </joint>

  <link name="lidar_link"/>

  <!-- *********************** GPS SETUP **********************************  -->
  <joint name="gps_joint" type="fixed">
    <parent link="base_link"/>
    <child link="gps_link"/>
    <origin xyz="0.10 0 0.05" rpy="0 0 0"/>
  </joint>

  <link name="gps_link"/>

</robot>
